<robot name="robot_boat">
  
  <link name="caja">
    <inertial>
      <origin xyz="-0.00350655617226021 0.0057870557154398 0.100314646324909" rpy="0 0 0" />
      <mass value="0.315668074424316" />
      <inertia ixx="0.00106952247168509" ixy="-6.35663584540256E-08" ixz="4.48722793894617E-07" iyy="0.00147003359417461" iyz="1.732567854706E-06" izz="0.000700072373673693" />
    </inertial>
    <visual>
      <geometry>
        <mesh filename="package://robot_boat/meshes/caja.STL"/>
      </geometry>
      <material name="azul_claro">
        <color rgba="0.792156862745098 0.819607843137255 0.933333333333333 1"/>
      </material>
    </visual>
    <collision>
      <geometry>
        <mesh filename="package://robot_boat/meshes/caja.STL"/>
      </geometry>
    </collision>
  </link>

  <link name="punta">
    <inertial>
      <origin xyz="3.27284758360044E-06 -0.00433760804571402 0.0273160015482659" rpy="0 0 0" />
      <mass value="0.0716405181094412" />
      <inertia ixx="5.44743781091978E-05" ixy="1.86774753169867E-09" ixz="6.76801340593279E-09" iyy="9.58237376978415E-05" iyz="-6.17934926455551E-06" izz="0.000101029420324114" />
    </inertial>
    <visual>
      <geometry>
        <mesh filename="package://robot_boat/meshes/punta.STL"/>
      </geometry>
      <material name="naranja">
        <color rgba="1 0.549019607843137 0 1"/>
      </material>
    </visual>
    <collision>
      <geometry>
        <mesh filename="package://robot_boat/meshes/punta.STL"/>
      </geometry>
    </collision>
  </link>

  <joint name="punta" type="fixed">
    <origin xyz="-0.0034915 0.02 0.018168" rpy="1.5708 0 0" />
    <parent link="caja"/>
    <child link="punta"/>
  </joint>

  <link name="motor1">
    <inertial>
      <origin xyz="0.0248078639783107 0 0" rpy="0 0 0" />
      <mass value="0.0338272475621472" />
      <inertia ixx="3.59775886940148E-06" ixy="-8.70714672756417E-24" ixz="-9.65307491393635E-22" iyy="1.02720341448678E-05" iyz="0" izz="1.02720341448678E-05" />
    </inertial>
    <visual>
      <geometry>
        <mesh filename="package://robot_boat/meshes/motor1.STL"/>
      </geometry>
      <material name="gris_claro">
        <color rgba="0.796078431372549 0.823529411764706 0.937254901960784 1"/>
      </material>
    </visual>
    <collision>
      <geometry>
        <mesh filename="package://robot_boat/meshes/motor1.STL"/>
      </geometry>
    </collision>
  </link>

  <joint name="motor1" type="continuous">
    <origin xyz="-0.04 -0.12 0.02" rpy="0 1.5708 0" />
    <parent link="caja"/>
    <child link="motor1"/>
    <axis xyz="1 0 0"/>
    <limit effort="10.0" velocity="10.0"/>
    <dynamics damping="0.1" friction="0.05"/>
  </joint>

  <link name="motor2">
    <inertial>
      <origin xyz="0.0248078639783108 -6.93889390390723E-18 0" rpy="0 0 0" />
      <mass value="0.0338272475621472" />
      <inertia ixx="3.59775886940148E-06" ixy="3.03672443546408E-22" ixz="-1.21326837735656E-21" iyy="1.02720341448678E-05" iyz="0" izz="1.02720341448678E-05" />
    </inertial>
    <visual>
      <geometry>
        <mesh filename="package://robot_boat/meshes/motor2.STL"/>
      </geometry>
      <material name="gris_claro">
        <color rgba="0.796078431372549 0.823529411764706 0.937254901960784 1"/>
      </material>
    </visual>
    <collision>
      <geometry>
        <mesh filename="package://robot_boat/meshes/motor2.STL"/>
      </geometry>
    </collision>
  </link>

  <joint name="motor2" type="continuous">
    <origin xyz="0.04 -0.12 0.02" rpy="0 1.5708 0" />
    <parent link="caja"/>
    <child link="motor2"/>
    <axis xyz="1 0 0"/>
    <limit effort="10.0" velocity="10.0"/>
    <dynamics damping="0.1" friction="0.05"/>
  </joint>

</robot>
